Workbook

Sheet  OLD HR AND ADMIN BUDGET
B2: SohCahToa Holdings Departmental Template
B3: HR and Admin Budget
B4: Expense Heads | C4: January | D4: February | E4: March | F4: April | G4: May | H4: June | I4: July | J4: August | K4: September | L4: October | M4: November | N4: December | O4: Total
B5: Rent | C5: ='Input Worksheet'!C49 -> 0 | D5: ='Input Worksheet'!D49 -> 0 | E5: ='Input Worksheet'!E49 -> 34900000 | F5: ='Input Worksheet'!F49 -> 0 | G5: ='Input Worksheet'!G49 -> 0 | H5: ='Input Worksheet'!H49 -> 21861657 | I5: ='Input Worksheet'!I49 -> 0 | J5: ='Input Worksheet'!J49 -> 0 | ... N5: ='Input Worksheet'!N49 -> 4492800 | O5: =SUM(C5:N5) -> 64710457
B6: Birthday Gifts | C6: ='Input Worksheet'!C54 -> 40000 | D6: 40000 | E6: ='Input Worksheet'!E54 -> 240000 | F6: ='Input Worksheet'!F54 -> 40000 | G6: ='Input Worksheet'!G54 -> 80000 | H6: ='Input Worksheet'!H54 -> 80000 | I6: ='Input Worksheet'!I54 -> 80000 | J6: ='Input Worksheet'!J54 -> 280000 | K6: ='Input Worksheet'!K54 -> 400000 | L6: ='Input Worksheet'!L54 -> 120000 | ... N6: ='Input Worksheet'!N54 -> 80000 | O6: =SUM(C6:N6) -> 1880000
B7: Communication | C7: ='Input Worksheet'!#REF! -> #REF! | D7: ='Input Worksheet'!#REF! -> #REF! | E7: ='Input Worksheet'!#REF! -> #REF! | F7: ='Input Worksheet'!#REF! -> #REF! | G7: ='Input Worksheet'!#REF! -> #REF! | H7: ='Input Worksheet'!#REF! -> #REF! | I7: ='Input Worksheet'!#REF! -> #REF! | J7: ='Input Worksheet'!#REF! -> #REF! | ... N7: ='Input Worksheet'!#REF! -> #REF! | O7: =SUM(C7:N7) -> #REF!
B8: Insurance | C8: ='Input Worksheet'!C28 -> 7042958.1 | D8: ='Input Worksheet'!D28 -> 5146814.6 | E8: ='Input Worksheet'!E28 -> 3355941.4 | F8: ='Input Worksheet'!F28 -> 3853173.4 | G8: ='Input Worksheet'!G28 -> 843380.87 | H8: ='Input Worksheet'!H28 -> 8073232 | I8: ='Input Worksheet'!I28 -> 4177173.4 | J8: ='Input Worksheet'!J28 -> 0 | ... N8: ='Input Worksheet'!N28 -> 8600000 | O8: =SUM(C8:N8) -> 49440764
B9: Repairs and Maintenance | C9: ='Input Worksheet'!C42 -> 405000 | D9: ='Input Worksheet'!D42 -> 300000 | E9: ='Input Worksheet'!E42 -> 621000 | F9: ='Input Worksheet'!F42 -> 500000 | G9: ='Input Worksheet'!G42 -> 500000 | H9: ='Input Worksheet'!H42 -> 800000 | I9: ='Input Worksheet'!I42 -> 500000 | J9: ='Input Worksheet'!J42 -> 542000 | ... N9: ='Input Worksheet'!N42 -> 1750000 | O9: =SUM(C9:N9) -> 8481000
B10: Fuelling | C10: ='Input Worksheet'!C61 -> 2800000 | D10: ='Input Worksheet'!D61 -> 3000000 | E10: ='Input Worksheet'!E61 -> 3070000 | F10: ='Input Worksheet'!F61 -> 3499600 | G10: ='Input Worksheet'!G61 -> 3499600 | H10: ='Input Worksheet'!H61 -> 3569600 | I10: ='Input Worksheet'!I61 -> 4124000.1 | J10: ='Input Worksheet'!J61 -> 4904375.3 | ... N10: ='Input Worksheet'!N61 -> 7168634.4 | O10: =SUM(C10:N10) -> 55782767
B11: Travelling Expense | C11: ='Input Worksheet'!C92 -> 7000000 | D11: ='Input Worksheet'!D92 -> 7000000 | E11: ='Input Worksheet'!E92 -> 7000000 | F11: ='Input Worksheet'!F92 -> 16600000 | G11: ='Input Worksheet'!G92 -> 16600000 | H11: ='Input Worksheet'!H92 -> 16600000 | I11: ='Input Worksheet'!I92 -> 32200000 | J11: ='Input Worksheet'!J92 -> 32200000 | ... N11: ='Input Worksheet'!N92 -> 47800000 | O11: =SUM(C11:N11) -> 310800000
B12: Team Bonding | C12: ='Input Worksheet'!C66 -> 897000 | D12: ='Input Worksheet'!D66 -> 975000 | E12: ='Input Worksheet'!E66 -> 2757000 | F12: ='Input Worksheet'!F66 -> 1209000 | G12: ='Input Worksheet'!G66 -> 1209000 | H12: ='Input Worksheet'!H66 -> 3054000 | I12: ='Input Worksheet'!I66 -> 1326000 | J12: ='Input Worksheet'!J66 -> 1326000 | ... N12: ='Input Worksheet'!N66 -> 1326000 | O12: =SUM(C12:N12) -> 20037000
B13: General office Expenses | C13: ='Input Worksheet'!C72 -> 603417.62 | D13: ='Input Worksheet'!D72 -> 588432 | E13: ='Input Worksheet'!E72 -> 1465052.3 | F13: ='Input Worksheet'!F72 -> 953259.84 | G13: ='Input Worksheet'!G72 -> 1211388.8 | H13: ='Input Worksheet'!H72 -> 1348444.4 | I13: ='Input Worksheet'!I72 -> 1480432.7 | J13: ='Input Worksheet'!J72 -> 1268788.8 | ... N13: ='Input Worksheet'!N72 -> 1522288.8 | O13: =SUM(C13:N13) -> 15060112
B14: Transportation | D14: 50000 | E14: 50000 | F14: 50000 | G14: 50000 | H14: 50000 | I14: 50000 | J14: 50000 | K14: 50000 | L14: 50000 | M14: 50000 | N14: 50000 | O14: =SUM(C14:N14) -> 550000
B15: Training and Team building | C15: ='Input Worksheet'!C76 -> 30000000 | D15: ='Input Worksheet'!D76 -> 0 | E15: ='Input Worksheet'!E76 -> 0 | F15: ='Input Worksheet'!F76 -> 0 | G15: ='Input Worksheet'!G76 -> 0 | H15: ='Input Worksheet'!H76 -> 0 | I15: ='Input Worksheet'!I76 -> 0 | J15: ='Input Worksheet'!J76 -> 0 | ... N15: ='Input Worksheet'!N76 -> 0 | O15: =SUM(C15:N15) -> 30000000
B16: Staff Events | C16: ='Input Worksheet'!C81 -> 0 | D16: ='Input Worksheet'!D81 -> 0 | E16: ='Input Worksheet'!E81 -> 0 | F16: ='Input Worksheet'!F81 -> 0 | G16: ='Input Worksheet'!G81 -> 0 | H16: ='Input Worksheet'!H81 -> 0 | I16: ='Input Worksheet'!I81 -> 0 | J16: ='Input Worksheet'!J81 -> 0 | ... N16: ='Input Worksheet'!N81 -> 25800000 | O16: =SUM(C16:N16) -> 29919615
B17: Sports and Fitness | C17: ='Input Worksheet'!C35 -> 2365333.3 | D17: ='Input Worksheet'!D35 -> 2311333.3 | E17: ='Input Worksheet'!E35 -> 2661333.3 | F17: ='Input Worksheet'!F35 -> 3287086 | G17: ='Input Worksheet'!G35 -> 3179086 | H17: ='Input Worksheet'!H35 -> 3179086 | I17: ='Input Worksheet'!I35 -> 3413006.6 | J17: ='Input Worksheet'!J35 -> 3305006.6 | ... N17: ='Input Worksheet'!N35 -> 3462382.3 | O17: =SUM(C17:N17) -> 37393425
B18: Personnel Cost | C18: ='Input Worksheet'!C21 -> 13641222 | D18: ='Input Worksheet'!D21 -> 16237204 | E18: ='Input Worksheet'!E21 -> 27949214 | F18: ='Input Worksheet'!F21 -> 26994693 | G18: ='Input Worksheet'!G21 -> 18287995 | H18: ='Input Worksheet'!H21 -> 32768566 | I18: ='Input Worksheet'!I21 -> 38459526 | J18: ='Input Worksheet'!J21 -> 20303065 | ... N18: ='Input Worksheet'!N21 -> 64597783 | O18: =SUM(C18:N18) -> 3.5050137e+08
B19: Capital Expenditure | C19: ='Capital Expenditure'!C9 -> 0 | D19: ='Capital Expenditure'!D9 -> 0 | E19: ='Capital Expenditure'!E9 -> 0 | F19: ='Capital Expenditure'!F9 -> 0 | G19: ='Capital Expenditure'!G9 -> 0 | H19: ='Capital Expenditure'!H9 -> 0 | I19: ='Capital Expenditure'!I9 -> 0 | J19: ='Capital Expenditure'!J9 -> 0 | ... N19: ='Capital Expenditure'!N9 -> 0 | O19: =SUM(C19:N19) -> 0
B20: Total | C20: =SUM(C5:C19) -> #REF! | D20: =SUM(D5:D19) -> #REF! | E20: =SUM(E5:E19) -> #REF! | F20: =SUM(F5:F19) -> #REF! | G20: =SUM(G5:G19) -> #REF! | H20: =SUM(H5:H19) -> #REF! | I20: =SUM(I5:I19) -> #REF! | J20: =SUM(J5:J19) -> #REF! | ... O20: =SUM(O5:O19) -> #REF!
F26: =SUM(F17:K17) -> 19668278

Sheet Comments and Notes (2)Old
C3: The 30% inflation rate forecasted is based on KPMG's inflation forecast for 2024
C5: Communication Expense | D5: Comments/Note
C6: Airtime and Data | D6: This is based on a credit limit of #10,000 for 27 staff per month
C7: CUG Subscription | D7: The cost is #1,000 per line. This amount would be paid at the end of the year for all lines for 1 year
C8: Office Internet | D8: The monthly cost of internet ( hyperia) is #215,000 and this is prepaid quarterly. This cost was inflated by 30% for the first 2 quarters and then by another 10%.
C9: Total
C11: Personnel Expenses
C12: Salaries and Allowance | D12: The current salary amount is based on the newly approved salary review structure for all existing roles
C13: Leave Allowance | D13: This is 10% of the annual basic salary payable at each employees work anniversary
C14: Bonus | D14: The maximum performance bonus is 75% for each quarter, which is paid in the following month
C15: 13th Month Salary | D15: 100% of employee gross salary payable in December
C16: Promotion | D16: A 25% increment was factored into this computation
C17: Staff end of the year package | D17: 1 bag of rice @ #58,000 for one person, half bag of rice@ #30,000 for 27 people, 10 liters oil @ #20,000 for 1 person, 5 liters oil @ #10,000 for 4 people and 3.5 liters oil @ #6,000 for 22 staff. Inflation of 30% is factored and this brings it to #1,149,600.
C18: Staff Training and development | D18: The budget is #100,000 per employee for each quarter, The total is the cost for 27 employees for 4 quarters
C19: New Staff Salary | D19: This is based on their roles and the proposed new salary structure
C20: Bonus for new staff | D20: The 9 new staff will be eligible to bonus. This will be paid only upon confirmation.
C21: Long service award | D21: Company's budget is #1,100,000 and there are 5 eligible staff in 2024
C22: Employer's Pension | D22: This is 10% of the BTH of all employees salary payable monthly
C23: Employer's Pension (New Staff) | D23: This is 10% of BHT of new staff
... C29: gency | D29: The sum of N3,000,000 is projected to cover gratuity for exiting staff and any other related cost.
C30: Total
C32: Insurance
C33: Hmo | D33: 2 platinum plan @ #570,236, 62 sliver plan @ #99,873 all employees and dependants including 9 new staff with 3 dependants each
C34: Group Life | D34: The premium for 27 employees would be #2, 223,817.27. An inflation rate of 30% was factored in
C35: Fire & Buglary | D35: The premium is #271,823
C36: Vehicle | D36: The insurance for the pool car is due in February and Stallion MG is due in December
C37: Total
C40: Sport and Fitness
C41: Field usage and aerobics | D41: The field costs a total of #1,440,000 @ #4,000 for 20 players twice a month #160,000 for 12 months(1,920,000), while aerobics cost 100,000 per month (1,200,000)bringin the total to #3,120,000. A 30% inflation rate was also factored in.
C42: Entertainment | D42: The current cost of refreshment is #109,240 per session and session would hold twice a month and 30% inflation rate was factored
C43: Players Logistics | D43: Players get #4,000 for logistics. Usually, about 10 players train per session and we have 2 sessions in a month. This briings the total to 80,000 per month. However, we project that the number of players may increase by at most 5 players which brings the total to 100,000
C44: Total
C47: Repairs and Maintenance
C48: Vehicle Repairs | D48: This is based on the repairs done in 2023 and porated through out the year, as specific time can not be determined
C49: Motor vehicle renewal | D49: When license would be renewed @ #25,000 each when due as stated in the input worksheet
C50: Vehicle Maintance | D50: The vehicles are serviced every 3 months @ #53,6000 each
C51: Total
C54: Rent Related
C55: Annual Rent | D55: Company rent is due in May 2024, and it would be renewed for two year
C56: Sevice charges (annually) | D56: The service charge remains the same
...

Sheet Input Worksheet (2) Old
C1: January | D1: February | E1: March | F1: April | G1: May | H1: June | I1: July | J1: August | K1: September | L1: October | M1: November | N1: December | O1: Total
B2: Communication Expense
B3: Airtime and Data | C3: =270000*1.3 -> 351000 | D3: =270000*1.3 -> 351000 | E3: =270000*1.3 -> 351000 | F3: =C3*1.1 -> 386100 | G3: =D3*1.1 -> 386100 | H3: =E3*1.1 -> 386100 | I3: =F3*1.1 -> 424710 | J3: =G3*1.1 -> 424710 | K3: =H3*1.1 -> 424710 | L3: =I3*1.1 -> 467181 | M3: =J3*1.1 -> 467181 | N3: =K3*1.1 -> 467181 | O3: =SUM(C3:N3) -> 4886973
B4: CUG Subscription | N4: =300000*1.3 -> 390000 | O4: =SUM(C4:N4) -> 390000
B5: Office Internet | D5: =645000+(645000*0.3) -> 838500 | G5: =D5 -> 838500 | J5: =G5*1.2 -> 1006200 | M5: =J5 -> 1006200 | O5: =SUM(C5:N5) -> 3689400
B6: Total | C6: =SUM(C3:C5) -> 351000 | D6: =SUM(D3:D5) -> 1189500 | E6: =SUM(E3:E5) -> 351000 | F6: =SUM(F3:F5) -> 386100 | G6: =SUM(G3:G5) -> 1224600 | H6: =SUM(H3:H5) -> 386100 | I6: =SUM(I3:I5) -> 424710 | J6: =SUM(J3:J5) -> 1430910 | ... O6: =SUM(O3:O5) -> 8966373
B8: Personnel Expenses
B9: Salaries and Allowance | C9: 6886501.5 | D9: 6886501.5 | E9: 6886501.5 | F9: 6886501.5 | G9: 6886501.5 | H9: 6886501.5 | I9: 6886501.5 | J9: 6886501.5 | K9: 6886501.5 | L9: 6886501.5 | M9: 6886501.5 | N9: 6886501.5 | O9: =SUM(C9:N9) -> 82638017
B10: Leave Allowance | E10: 150000 | F10: 685742 | H10: =300000+465134.06 -> 765134.06 | I10: 150000 | K10: =300000+597864 -> 897864 | L10: 382570.29 | M10: 150000 | N10: 298494.2 | O10: =SUM(C10:N10) -> 3479804.6
B11: Bonus | C11: =C9*0.75 -> 5164876.1 | I11: =G9*0.75 -> 5164876.1 | L11: =J9*0.75 -> 5164876.1 | O11: =SUM(C11:N11) -> 15494628
B12: 13th Month Salary | N12: =N9+N16 -> 9786916 | O12: =SUM(C12:N12) -> 9786916
B13: Promotion | I13: =C9*0.25 -> 1721625.4
B14: Staff end of the year package | N14: =1060000*1.3 -> 1378000 | O14: =SUM(C14:N14) -> 1378000
B15: Staff Training and development | E15: 2700000 | H15: 2700000 | K15: 2700000 | N15: 2700000 | O15: =SUM(C15:N15) -> 10800000
B16: New Staff Salary | C16: 2900414.6 | D16: 2900414.6 | E16: 2900414.6 | F16: 2900414.6 | G16: 2900414.6 | H16: 2900414.6 | I16: 2900414.6 | J16: 2900414.6 | K16: 2900414.6 | L16: 2900414.6 | M16: 2900414.6 | N16: 2900414.6 | O16: =SUM(C16:N16) -> 34804975
B17: Bonus for new staff | I17: =I16*0.75 -> 2175310.9 | N17: =N16*0.75 -> 2175310.9 | O17: =SUM(C17:N17) -> 4350621.8
B18: Long service award | L18: 5500000 | O18: =SUM(C18:N18) -> 5500000
B19: Employer's Pension | C19: 497114.94 | D19: 497114.94 | E19: 497114.94 | F19: 497114.94 | G19: 497114.94 | H19: 497114.94 | I19: 497114.94 | J19: 497114.94 | K19: 497114.94 | L19: 497114.94 | M19: 497114.94 | N19: 497114.94 | O19: =SUM(C19:N19) -> 5965379.2
B20: Employer's Pension (New Staff) | C20: 113399.46 | D20: 113399.46 | E20: 113399.46 | F20: 113399.46 | G20: 113399.46 | H20: 113399.46 | I20: 113399.46 | J20: 113399.46 | K20: 113399.46 | L20: 113399.46 | M20: 113399.46 | N20: 113399.46 | O20: =SUM(C20:N20) -> 1360793.5
B21: NSITF Regularization | E21: 2761297 | O21: =SUM(C21:N21) -> 2761297
B22: NSITF | E22: =N12*12 *0.01 -> 1174429.9 | O22: =SUM(C22:N22) -> 1174429.9
B23: ITF | L23: =N12*12 *0.01 -> 1174429.9 | O23: =SUM(C23:N23) -> 1174429.9
B24: Pre employment Medicals | C24: =144000+(144000*0.3) -> 187200 | O24: =SUM(C24:N24) -> 187200
B25: Onboarding | C25: =35700+(35700*0.3) -> 46410 | O25: =SUM(C25:N25) -> 46410
B26: Contigency | N26: 3000000 | O26: =SUM(C26:N26) -> 3000000
B27: Total | C27: =SUM(C9:C25) -> 15795917 | D27: =SUM(D9:D25) -> 10397430 | E27: =SUM(E9:E25) -> 17183157 | F27: =SUM(F9:F25) -> 11083172 | G27: =SUM(G9:G25) -> 10397430 | H27: =SUM(H9:H25) -> 13862564 | I27: =SUM(I9:I25) -> 19609243 | J27: =SUM(J9:J25) -> 10397430 | ... N27: =SUM(N9:N25) -> 26736152 | O27: =SUM(O9:O26) -> 1.839029e+08
B29: Insurance
B30: Hmo | H30: =6762362+(6762362*0.3) -> 8791070.6 | O30: =SUM(C30:N30) -> 8791070.6
B31: Group Life | L31: =2223817.27+(2223817.27*0.3) -> 2890962.5 | O31: =SUM(C31:N31) -> 2890962.5
B32: Fire & Buglary | G32: =271823*1.3 -> 353369.9 | O32: =SUM(C32:N32) -> 353369.9
B33: Vehicle | D33: =110000*1.3 -> 143000 | N33: =351000*1.3 -> 456300 | O33: =SUM(C33:N33) -> 599300
B34: Total | C34: =SUM(C30:C33) -> 0 | D34: =SUM(D30:D33) -> 143000 | E34: =SUM(E30:E33) -> 0 | F34: =SUM(F30:F33) -> 0 | G34: =SUM(G30:G33) -> 353369.9 | H34: =SUM(H30:H33) -> 8791070.6 | I34: =SUM(I30:I33) -> 0 | J34: =SUM(J30:J33) -> 0 | ... O34: =SUM(O30:O33) -> 12634703
B37: Sport and Fitness
B38: Field usage and aerobics | C38: =380000*1.3 -> 494000 | D38: =380000*1.3 -> 494000 | E38: =380000*1.3 -> 494000 | F38: =C38*1.1 -> 543400 | G38: =D38*1.1 -> 543400 | H38: =E38*1.1 -> 543400 | I38: =F38*1.1 -> 597740 | J38: =G38*1.1 -> 597740 | K38: =H38*1.1 -> 597740 | L38: =I38*1.1 -> 657514 | M38: =J38*1.1 -> 657514 | N38: =K38*1.1 -> 657514 | O38: =SUM(C38:N38) -> 6877962
B39: Entertainment | C39: =109240*1.3 -> 142012 | D39: =109240*1.3 -> 142012 | E39: =109240*1.3 -> 142012 | F39: 131008 | G39: 131008 | H39: 131008 | I39: 131008 | J39: 131008 | K39: 131008 | L39: 131008 | M39: 131008 | N39: 131008 | O39: =SUM(C39:N39) -> 1605108
B40: Players Logistics | C40: 200000 | D40: 200000 | E40: 200000 | F40: 200000 | G40: 200000 | H40: 200000 | I40: 200000 | J40: 200000 | K40: 200000 | L40: 200000 | M40: 200000 | N40: 200000 | O40: =SUM(C40:N40) -> 2400000
B41: Total | C41: =SUM(C38:C40) -> 836012 | D41: =SUM(D38:D40) -> 836012 | E41: =SUM(E38:E40) -> 836012 | F41: =SUM(F38:F40) -> 874408 | G41: =SUM(G38:G40) -> 874408 | H41: =SUM(H38:H40) -> 874408 | I41: =SUM(I38:I40) -> 928748 | J41: =SUM(J38:J40) -> 928748 | ... O41: =SUM(O38:O40) -> 10883070
G43: =SUM(F38:K38) -> 3423420
B44: Repairs and Maintenance
B45: Vehicle Repairs | C45: =50000*1.3 -> 65000 | D45: =50000*1.3 -> 65000 | E45: =50000*1.3 -> 65000 | F45: =C45*1.1 -> 71500 | G45: =D45*1.1 -> 71500 | H45: =E45*1.1 -> 71500 | I45: =F45*1.1 -> 78650 | J45: =G45*1.1 -> 78650 | K45: =H45*1.1 -> 78650 | L45: 50000 | M45: 50000 | N45: 50000 | O45: =SUM(C45:N45) -> 795450
...

Sheet HR AND ADMIN BUDGET
B2: SohCahToa Holdings Departmental Template
B3: HR and Admin Budget
B4: Expense Heads | C4: January | D4: February | E4: March | F4: April | G4: May | H4: June | I4: July | J4: August | K4: September | L4: October | M4: November | N4: December | O4: Total
B5: Rent | C5: ='Input Worksheet'!C49 -> 0 | D5: ='Input Worksheet'!D49 -> 0 | E5: ='Input Worksheet'!E49 -> 34900000 | F5: ='Input Worksheet'!F49 -> 0 | G5: ='Input Worksheet'!G49 -> 0 | H5: ='Input Worksheet'!H49 -> 21861657 | I5: ='Input Worksheet'!I49 -> 0 | J5: ='Input Worksheet'!J49 -> 0 | ... N5: ='Input Worksheet'!N49 -> 4492800 | O5: =SUM(C5:N5) -> 64710457
B6: Birthday Gifts | C6: ='Input Worksheet'!C54 -> 40000 | D6: ='Input Worksheet'!D54 -> 40000 | E6: ='Input Worksheet'!E54 -> 240000 | F6: ='Input Worksheet'!F54 -> 40000 | G6: ='Input Worksheet'!G54 -> 80000 | H6: ='Input Worksheet'!H54 -> 80000 | I6: ='Input Worksheet'!I54 -> 80000 | J6: ='Input Worksheet'!J54 -> 280000 | ... N6: ='Input Worksheet'!N54 -> 80000 | O6: =SUM(C6:N6) -> 1880000
B7: Insurance | C7: ='Input Worksheet'!C28 -> 7042958.1 | D7: ='Input Worksheet'!D28 -> 5146814.6 | E7: ='Input Worksheet'!E28 -> 3355941.4 | F7: ='Input Worksheet'!F28 -> 3853173.4 | G7: ='Input Worksheet'!G28 -> 843380.87 | H7: ='Input Worksheet'!H28 -> 8073232 | I7: ='Input Worksheet'!I28 -> 4177173.4 | J7: ='Input Worksheet'!J28 -> 0 | ... N7: ='Input Worksheet'!N28 -> 8600000 | O7: =SUM(C7:N7) -> 49440764
B8: Repairs and Maintenance | C8: ='Input Worksheet'!C42 -> 405000 | D8: ='Input Worksheet'!D42 -> 300000 | E8: ='Input Worksheet'!E42 -> 621000 | F8: ='Input Worksheet'!F42 -> 500000 | G8: ='Input Worksheet'!G42 -> 500000 | H8: ='Input Worksheet'!H42 -> 800000 | I8: ='Input Worksheet'!I42 -> 500000 | J8: ='Input Worksheet'!J42 -> 542000 | ... N8: ='Input Worksheet'!N42 -> 1750000 | O8: =SUM(C8:N8) -> 8481000
B9: Fuelling | C9: ='Input Worksheet'!C61 -> 2800000 | D9: ='Input Worksheet'!D61 -> 3000000 | E9: ='Input Worksheet'!E61 -> 3070000 | F9: ='Input Worksheet'!F61 -> 3499600 | G9: ='Input Worksheet'!G61 -> 3499600 | H9: ='Input Worksheet'!H61 -> 3569600 | I9: ='Input Worksheet'!I61 -> 4124000.1 | J9: ='Input Worksheet'!J61 -> 4904375.3 | ... N9: ='Input Worksheet'!N61 -> 7168634.4 | O9: =SUM(C9:N9) -> 55782767
B10: Travelling Expense | C10: ='Input Worksheet'!C92 -> 7000000 | H10: ='Input Worksheet'!H92 -> 16600000 | M10: ='Input Worksheet'!M92 -> 47800000 | O10: =SUM(C10:N10) -> 71400000
B11: Team Bonding | C11: ='Input Worksheet'!C66 -> 897000 | D11: ='Input Worksheet'!D66 -> 975000 | E11: ='Input Worksheet'!E66 -> 2757000 | F11: ='Input Worksheet'!F66 -> 1209000 | G11: ='Input Worksheet'!G66 -> 1209000 | H11: ='Input Worksheet'!H66 -> 3054000 | I11: ='Input Worksheet'!I66 -> 1326000 | J11: ='Input Worksheet'!J66 -> 1326000 | ... N11: ='Input Worksheet'!N66 -> 1326000 | O11: =SUM(C11:N11) -> 20037000
B12: General office Expenses | C12: ='Input Worksheet'!C72 -> 603417.62 | D12: ='Input Worksheet'!D72 -> 588432 | E12: ='Input Worksheet'!E72 -> 1465052.3 | F12: ='Input Worksheet'!F72 -> 953259.84 | G12: ='Input Worksheet'!G72 -> 1211388.8 | H12: ='Input Worksheet'!H72 -> 1348444.4 | I12: ='Input Worksheet'!I72 -> 1480432.7 | J12: ='Input Worksheet'!J72 -> 1268788.8 | ... N12: ='Input Worksheet'!N72 -> 1522288.8 | O12: =SUM(C12:N12) -> 15060112
B13: Training and Team building | C13: ='Input Worksheet'!C76 -> 30000000 | D13: ='Input Worksheet'!D76 -> 0 | E13: ='Input Worksheet'!E76 -> 0 | F13: ='Input Worksheet'!F76 -> 0 | G13: ='Input Worksheet'!G76 -> 0 | H13: ='Input Worksheet'!H76 -> 0 | I13: ='Input Worksheet'!I76 -> 0 | J13: ='Input Worksheet'!J76 -> 0 | ... N13: ='Input Worksheet'!N76 -> 0 | O13: =SUM(C13:N13) -> 30000000
B14: Funmigation & Consultants | C14: ='Input Worksheet'!C86 -> 450000 | D14: ='Input Worksheet'!D86 -> 0 | E14: ='Input Worksheet'!E86 -> 5000000 | F14: ='Input Worksheet'!F86 -> 0 | G14: ='Input Worksheet'!G86 -> 0 | H14: ='Input Worksheet'!H86 -> 5580500 | I14: ='Input Worksheet'!I86 -> 0 | J14: ='Input Worksheet'!J86 -> 0 | ... N14: ='Input Worksheet'!N86 -> 0
B15: Staff Events | C15: ='Input Worksheet'!C81 -> 0 | D15: ='Input Worksheet'!D81 -> 0 | E15: ='Input Worksheet'!E81 -> 0 | F15: ='Input Worksheet'!F81 -> 0 | G15: ='Input Worksheet'!G81 -> 0 | H15: ='Input Worksheet'!H81 -> 0 | I15: ='Input Worksheet'!I81 -> 0 | J15: ='Input Worksheet'!J81 -> 0 | ... N15: ='Input Worksheet'!N81 -> 25800000 | O15: =SUM(C15:N15) -> 29919615
B16: Sports and Fitness | C16: ='Input Worksheet'!C35 -> 2365333.3 | D16: ='Input Worksheet'!D35 -> 2311333.3 | E16: ='Input Worksheet'!E35 -> 2661333.3 | F16: ='Input Worksheet'!F35 -> 3287086 | G16: ='Input Worksheet'!G35 -> 3179086 | H16: ='Input Worksheet'!H35 -> 3179086 | I16: ='Input Worksheet'!I35 -> 3413006.6 | J16: ='Input Worksheet'!J35 -> 3305006.6 | ... N16: ='Input Worksheet'!N35 -> 3462382.3 | O16: =SUM(C16:N16) -> 37393425
B17: Personnel Cost | C17: ='Input Worksheet'!C21 -> 13641222 | D17: ='Input Worksheet'!D21 -> 16237204 | E17: ='Input Worksheet'!E21 -> 27949214 | F17: ='Input Worksheet'!F21 -> 26994693 | G17: ='Input Worksheet'!G21 -> 18287995 | H17: ='Input Worksheet'!H21 -> 32768566 | I17: ='Input Worksheet'!I21 -> 38459526 | J17: ='Input Worksheet'!J21 -> 20303065 | ... N17: ='Input Worksheet'!N21 -> 64597783 | O17: =SUM(C17:N17) -> 3.5050137e+08
B18: Capital Expenditure | C18: 172000000 | D18: ='Capital Expenditure'!D9 -> 0 | F18: ='Capital Expenditure'!F9 -> 0 | G18: ='Capital Expenditure'!G9 -> 0 | H18: ='Capital Expenditure'!H9 -> 0 | I18: ='Capital Expenditure'!I9 -> 0 | J18: ='Capital Expenditure'!J9 -> 0 | K18: ='Capital Expenditure'!K9 -> 0 | L18: ='Capital Expenditure'!L9 -> 0 | M18: ='Capital Expenditure'!M9 -> 0 | N18: ='Capital Expenditure'!N9 -> 0 | O18: =SUM(C18:N18) -> 172000000
B19: Total | C19: =SUM(C5:C18) -> 2.3724493e+08 | D19: =SUM(D5:D18) -> 28598784 | E19: =SUM(E5:E18) -> 82019541 | F19: =SUM(F5:F18) -> 40336813 | G19: =SUM(G5:G18) -> 28810451 | H19: =SUM(H5:H18) -> 96915085 | I19: =SUM(I5:I18) -> 53560139 | J19: =SUM(J5:J18) -> 31929236 | ... O19: =SUM(O5:O18) -> 9.0660651e+08

Sheet Input Worksheet
C1: January | D1: February | E1: March | F1: April | G1: May | H1: June | I1: July | J1: August | K1: September | L1: October | M1: November | N1: December | O1: Total
B3: Personnel Expenses
B4: Salaries and Allowance | C4: 9789866.7 | D4: =SUM(C4,C11) -> 11688368 | E4: =SUM(D4,D11) -> 12118543 | F4: =SUM(E4,E11) -> 13384543 | G4: =SUM(F4,F11) -> 15686543 | H4: =SUM(G4,G11) -> 15686543 | I4: =SUM(H4,H11) -> 15686543 | J4: =SUM(I4,I11) -> 17186543 | K4: =SUM(J4,J11) -> 17186543 | ... N4: =SUM(M4,M11) -> 17186543 | O4: =SUM(C4:N4) -> 1.7997367e+08
B5: Leave Allowance | E5: 145663.79 | F5: 279, 185.316 | G5: 111793.5 | H5: =60047.352+182317.2 -> 242364.55 | I5: =70724.748+111793.5 -> 182518.25 | J5: =180600+180600+ 145663.79 -> 506863.79 | K5: =279185.316 +126114.68 +111793.5+378000 -> 895093.5 | L5: =174075.444 +174075.444+152917.2 -> 501068.09 | M5: =111793.5 +111793.5 -> 223587 | N5: =111793.5 +111793.5 -> 223587 | O5: =SUM(C5:N5) -> 3032539.5
B6: Bonus | F6: 8656342 | I6: 9789867 | L6: =SUM(C4,242000,242000,D11,E11) -> 11970042 | O6: =SUM(C6:N6) -> 30416251
B7: 13th Month Salary | N7: =N4 -> 17186543 | O7: =SUM(C7:N7) -> 17186543
B8: Promotion | I8: =(14742806.36-C4)+3000000 -> 7952939.7 | O8: =SUM(C8:N8) -> 7952939.7
B9: Staff end of the year package | N9: =0.2498*3993800+(3993800) -> 4991451.2 | O9: =SUM(C9:N9) -> 4991451.2
B10: Staff Training and development | E10: =400000*30 -> 12000000 | H10: =400000*33+1100000 -> 14300000 | I10: 575850 | K10: =400000*36 -> 14400000 | L10: 1025000 | M10: 985000 | N10: =400000*36 -> 14400000 | O10: =SUM(C10:N10) -> 57685850
B11: New Staff Salary | C11: =955987.17+ 942514.55 -> 1898501.7 | D11: =255175+175000 -> 430175 | E11: =422000+422000+422000 -> 1266000 | F11: =1200000+680000+422000 -> 2302000 | I11: =500000+500000+500000 -> 1500000 | O11: =SUM(C11:N11) -> 7396676.7
B12: Long service award | C12: =50000*2 -> 100000 | H12: 50000 | O12: =SUM(C12:N12) -> 150000
B13: Drivers' Salary | C13: 798454 | D13: 1136857 | E13: 1136857 | F13: =1136857+112801 -> 1249658 | G13: =1136857+112801 -> 1249658 | H13: =1136857+112801 -> 1249658 | I13: =1136857+112801 -> 1249658 | J13: =1136857+112801 -> 1249658 | K13: =1136857+112801 -> 1249658 | L13: =1136857+112801 -> 1249658 | M13: =1136857+112801 -> 1249658 | N13: =1136857+112801 -> 1249658 | O13: =SUM(C13:N13) -> 14319090
B14: NSITF Regularization | D14: =(O4+O11)*0.01 -> 1873703.5 | O14: =SUM(C14:N14) -> 1873703.5
B15: NSITF | O15: =SUM(C15:N15) -> 0
B16: ITF | L16: =(O4+O11)*0.01 -> 1873703.5 | O16: =SUM(C16:N16) -> 1873703.5
B17: Pre employment Medicals | C17: =44800*3 -> 134400 | D17: =44800*2 -> 89600 | E17: =44800*3 -> 134400 | F17: =44800*3 -> 134400 | I17: =F17 -> 134400 | O17: =SUM(C17:N17) -> 627200
B18: Onboarding | D18: =(4750+4500)*2 -> 18500 | E18: =(4750+4500)*3 -> 27750 | F18: =(4750+4500)*3 -> 27750 | I18: =F18 -> 27750 | J18: =$H18+0.03*$H18 -> 0 | K18: =$H18+0.03*$H18 -> 0 | L18: =$K18+0.02*$K18 -> 0 | M18: =$K18+0.02*$K18 -> 0 | N18: =$K18+0.02*$K18 -> 0 | O18: =SUM(C18:N18) -> 101750
B19: Contigency (Staff exit) | N19: 8000000 | O19: =SUM(C19:N19) -> 8000000
B20: Transportation Allowance | C20: =40000*23 -> 920000 | D20: =40000*25 -> 1000000 | E20: =40000*28 -> 1120000 | F20: =40000*31 -> 1240000 | G20: =40000*31 -> 1240000 | H20: =40000*31 -> 1240000 | I20: =40000*34 -> 1360000 | J20: =40000*34 -> 1360000 | K20: =40000*34 -> 1360000 | L20: =40000*34 -> 1360000 | M20: =40000*34 -> 1360000 | N20: =40000*34 -> 1360000 | O20: =SUM(C20:N20) -> 14920000
B21: Total | C21: =SUM(C4:C20) -> 13641222 | D21: =SUM(D4:D20) -> 16237204 | E21: =SUM(E4:E20) -> 27949214 | F21: =SUM(F4:F20) -> 26994693 | G21: =SUM(G4:G20) -> 18287995 | H21: =SUM(H4:H20) -> 32768566 | I21: =SUM(I4:I20) -> 38459526 | J21: =SUM(J4:J20) -> 20303065 | ... O21: =SUM(O4:O20) -> 3.5050137e+08
B23: Insurance
B24: Hmo | C24: =201556+251945.5+99873+99873 -> 653247.5 | D24: =(99873*3)*2 -> 599238 | E24: =(99873*3)*3 -> 898857 | F24: =(99873*3)*3 -> 898857 | H24: 7873232 | I24: =F24 -> 898857 | O24: =SUM(C24:N24) -> 11822288
B25: Group Life | C25: 2090710.6 | D25: 2183628.4 | E25: 2457084.4 | F25: 2954316.4 | I25: 3278316.4 | L25: =30/100*5613915.405+5613915.405 -> 7298090 | O25: =SUM(C25:N25) -> 20262146
B26: Fire & Buglary | G26: =30/100*353369.9+353369.9 -> 459380.87 | O26: =SUM(C26:N26) -> 459380.87
B27: Vehicle | C27: =1000000+3299000 -> 4299000 | D27: 2363948.2 | G27: 384000 | H27: 200000 | L27: 400000 | M27: 650000 | N27: =2850000+5750000 -> 8600000 | O27: =SUM(C27:N27) -> 16896948
B28: Total | C28: =SUM(C24:C27) -> 7042958.1 | D28: =SUM(D24:D27) -> 5146814.6 | E28: =SUM(E24:E27) -> 3355941.4 | F28: =SUM(F24:F27) -> 3853173.4 | G28: =SUM(G24:G27) -> 843380.87 | H28: =SUM(H24:H27) -> 8073232 | I28: =SUM(I24:I27) -> 4177173.4 | J28: =SUM(J24:J27) -> 0 | ... O28: =SUM(O24:O27) -> 49440764
B31: Sport and Fitness
B32: Field usage and aerobics | C32: =303333.3+100000 -> 403333.3 | D32: =303333.3+100000 -> 403333.3 | E32: =303333.3+100000 -> 403333.3 | F32: =$E32*(24.98/100)+$E32 -> 504085.96 | G32: =$E32*(24.98/100)+$E32 -> 504085.96 | H32: =$E32*(24.98/100)+$E32 -> 504085.96 | I32: =$H32*(24.98/100)+$H32 -> 630006.63 | J32: =$H32*(24.98/100)+$H32 -> 630006.63 | K32: =$H32*(24.98/100)+$H32 -> 630006.63 | L32: =$K32*(24.98/100)+$K32 -> 787382.29 | M32: =$K32*(24.98/100)+$K32 -> 787382.29 | N32: =$K32*(24.98/100)+$K32 -> 787382.29 | O32: =SUM(C32:N32) -> 6974424.5
B33: Entertainment | C33: =350000*4 -> 1400000 | D33: =350000*4 -> 1400000 | E33: =350000*5 -> 1750000 | F33: =$E33*1.3 -> 2275000 | G33: =$E33*1.3 -> 2275000 | H33: =$E33*1.3 -> 2275000 | I33: =$E33*1.3 -> 2275000 | J33: =$E33*1.3 -> 2275000 | K33: =$E33*1.3 -> 2275000 | L33: =$E33*1.3 -> 2275000 | M33: =$E33*1.3 -> 2275000 | N33: =$E33*1.3 -> 2275000 | O33: =SUM(C33:N33) -> 25025000
B34: Players Logistics | C34: =(100000*4)+162000 -> 562000 | D34: =(100000*4)+108000 -> 508000 | E34: =(100000*4)+108000 -> 508000 | F34: =(100000*4)+108000 -> 508000 | G34: =100000*4 -> 400000 | H34: =100000*4 -> 400000 | I34: =(100000*4)+108000 -> 508000 | J34: =100000*4 -> 400000 | K34: =100000*4 -> 400000 | L34: =100000*4 -> 400000 | M34: =100000*4 -> 400000 | N34: =100000*4 -> 400000 | O34: =SUM(C34:N34) -> 5394000
B35: Total | C35: =SUM(C32:C34) -> 2365333.3 | D35: =SUM(D32:D34) -> 2311333.3 | E35: =SUM(E32:E34) -> 2661333.3 | F35: =SUM(F32:F34) -> 3287086 | G35: =SUM(G32:G34) -> 3179086 | H35: =SUM(H32:H34) -> 3179086 | I35: =SUM(I32:I34) -> 3413006.6 | J35: =SUM(J32:J34) -> 3305006.6 | ... O35: =SUM(O32:O34) -> 37393425
B38: Repairs and Maintenance
B39: Vehicle Repairs | C39: 300000 | D39: 300000 | E39: 300000 | F39: 500000 | G39: 500000 | H39: 500000 | I39: 500000 | J39: 500000 | K39: 500000 | L39: 750000 | M39: 750000 | N39: 750000 | O39: =SUM(C39:N39) -> 6150000
B40: Motor vehicle renewal | C40: 105000 | E40: 21000 | J40: 42000 | L40: =16500+4500 -> 21000 | M40: 42000 | O40: =SUM(C40:N40) -> 231000
B41: Vehicle Maintenance | E41: 300000 | H41: 300000 | K41: 500000 | N41: 1000000 | O41: =SUM(C41:N41) -> 2100000
B42: Total | C42: =SUM(C38:C41) -> 405000 | D42: =SUM(D38:D41) -> 300000 | E42: =SUM(E38:E41) -> 621000 | F42: =SUM(F38:F41) -> 500000 | G42: =SUM(G38:G41) -> 500000 | H42: =SUM(H38:H41) -> 800000 | I42: =SUM(I38:I41) -> 500000 | J42: =SUM(J38:J41) -> 542000 | ... N42: =SUM(N38:N41) -> 1750000 | O42: =SUM(O39:O41) -> 8481000
B45: Rent Related
B46: Annual Rent | E46: 30000000 | H46: 17199000 | O46: =SUM(C46:N46) -> 47199000
B47: Sevice charges (annually) | E47: 2500000 | H47: 1782656.8 | O47: =SUM(C47:N47) -> 4282656.8
B48: Electricity supply charges (monthly ) | E48: =800000*3 -> 2400000 | H48: =E48*1.2 -> 2880000 | K48: =H48*1.2 -> 3456000 | N48: =K48*1.3 -> 4492800 | O48: =SUM(C48:N48) -> 13228800
...

Sheet Comments and Notes
C3: The 24.98% inflation rate forecasted is based on Statistica's inflation forecast for 2025
C5: Communication Expense | D5: Comments/Note
C6: Airtime and Data
C7: CUG Subscription
C8: Office Internet
C9: Total
C11: Personnel Expenses
C12: Salaries and Allowance | D12: As at December 2024, the budget was N9,983,880.10. We included the net salary for the following roles: lead ICA, Financial Controller, BDC Officer, Finance Officer in January 2025 while HR/Admin Officer and Corporate Comms Officer. Key account managers (senior and junior), T.A and E.A were added in February 2025. We budgeted 243,000 in July for 3 corp. members at 81,000 each.
C13: Leave Allowance | D13: This is computed using 10% of the annual basic salary.
C14: Bonus | D14: The maximum performance bonus is 100% gross for each quarter, which is paid in the following month. Only confirmed employees are eligible and we factored in the number of eligible employees per quarter.
C15: 13th Month Salary | D15: 100% of employee gross salary payable in December
C16: Promotion | D16: Promotion is subject to performance. We calculated a 50% increment and added the sum of 3,000,000 to cover promotion to higher levels.
C17: Staff end of the year package | D17: We factored in a total of 15 new employees and adjusted the gifts according to their projected level. According to Statistica, the inflation rate for 2025 is 24.98%. We marked up using this percentage.
C18: Staff Training and development | D18: We budgeted N400,000 per employee per quarter. We are working with a total of 64 employees while factoring in special trainings in specific months.
C19: New Staff Salary | D19: The projection is based on the number of expected employees per month.
C20: Long service award | D20: Ayodele and titi will be paid N50,000 each for completing 5 years in 2024 while Damilola will be paid in June 2025.
C21: Drivers' Salary | D21: Each driver earns N112,801 monthly gross while the executive drivers earn N173,6725 monthly gross. We currently have 9 drivers and will be ionboarding 3 in February and 1 staff bus driver in April 2025.
C22: NSITF | D22: 1% of annual payroll
C23: ITF | D23: 1% of annual payroll
... C27: Transportation Allowance | D27: The sum of N40,000 is paid monthly to staff to auugment transportation expenses. This calculation was done based on the number of employees to be onboarded monthly.
C28: Total
C30: Insurance
C31: Hmo | D31: The Platinum plan costs N570236 (4 individuals are entitled to this). The corporate silver plan costs N99,873
C32: Group Life | D32: The premium is calculated as sum insured *3 of the annual salaries for each staff multiplied by 0.06.
C33: Fire & Buglary | D33: The premium is N353,369 and a 30% inflation rate was factored in.
C34: Vehicle | D34: We budgeted based on the insurance renewal dates of the existing vehicles and factored in the insurance renewal date for the staff bus in december.
C35: Total
C38: Sport and Fitness
C39: Field usage and aerobics | D39: We budgeted N350,000 monthly for field usage and added N100,000 payment to the aerobics instructor.
C40: Entertainment | D40: We considered the fact that aerobics and football training will be combined to determine that N350,000 would cover entertainment per week.
C41: Players Logistics | D41: This cost covers transportation fare given to the external players (N100,000) and purchase of training items such as boots etc.
C42: Total
C45: Repairs and Maintenance
C46: Vehicle Repairs | D46: We projected that the sum of N300,000 would be expended on vehicle repairs monthly for Q1, while N500,000 would be expended monthly for Q2 and Q3 and finally, N750000 would be expended in Q4
C47: Motor Vehicle Renewal | D47: Renewal of vehicle documents cost N21,000. In January, it is projected that we would acquire at least 5 new vehicles and the cost of registration was factored in, in January. We also considered the expiry date of the licences of existing vehicles.
C48: Vehicle Maintenance | D48: We budgeted the sum of N300,000 for vehicle maintenance in Q1 and Q2. This was increased to N500,000 in Q3 because we anticipate that there will be need to do more repairs toward the end of the year. We also factored in N1000000 in Q4 to also cover maintenance cost for new vehicles.
C49: Total
C52: Rent Related
C53: Annual Rent | D53: In 2024, our rent was increased to 17,199,000 per annum which is expected to be paid by June 1, 2025. We also prohjected that there will be need to rent a new office space and budgeted the sum of N30,000,000 to cover rent for the new office.
C54: Sevice charges (annually) | D54: The service charge was increased in 2025 to 1,782,656.78 and this would be paid along with the rent due in June 2025. We also budgeted the sum of N2,500,000.00 as service charge for the new office.
...

Sheet Employer's Pension (New Staff)
A3: Roles | B3: Projected Salary | C3: Pension
A4: T.A | B4: 346818.85 | C4: 14060.22
A5: ICA | B5: 603693.01 | C5: 28630.8
A6: Front Desk | B6: 266175 | C6: 10647
A7: Corp. Comms | B7: 346818.85 | C7: 14060.22
A8: Finance Officer | B8: 266175 | C8: 10647
A9: Account Manager 1 | B9: 266175 | C9: 10647
A10: Account Manager 2 | B10: 346818.85 | C10: 14060.22
A11: I.T | B11: 266175 | C11: 10647
A12: Driver | B12: 110565
A13: Driver | B13: 110565
A14: Total | B14: =SUM(B4:B13) -> 2929979.6 | C14: =SUM(C4:C13) -> 113399.46
C15: 313050.32
C16: =SUM(C14:C15) -> 426449.78

Sheet Capital Expenditure
B2: Assets | C2: January | D2: February | E2: March | F2: April | G2: May | H2: June | I2: July | J2: August | K2: September | L2: October | M2: November | N2: December | O2: Total
O3: ₦
B4: Motor Vehicle | O4: =SUM(C4:N4) -> 0
B5: File Cabinet | O5: =SUM(C5:N5) -> 0
B6: Furniture and Fittings | O6: =SUM(C6:N6) -> 0
O7: =SUM(C7:N7) -> 0
O8: =SUM(C8:N8) -> 0
B9: Total | C9: =SUM(C4:C8) -> 0 | D9: =SUM(D4:D8) -> 0 | E9: =SUM(E4:E8) -> 0 | F9: =SUM(F4:F8) -> 0 | G9: =SUM(G4:G8) -> 0 | H9: =SUM(H4:H8) -> 0 | I9: =SUM(I4:I8) -> 0 | J9: =SUM(J4:J8) -> 0 | ... O9: =SUM(O4:O8) -> 0
